{
    DataVersion: 3955,
    size: [5, 4, 4],
    data: [
        {pos: [0, 0, 0], state: "minecraft:dirt"},
        {pos: [0, 0, 1], state: "minecraft:dirt"},
        {pos: [0, 0, 2], state: "minecraft:dirt"},
        {pos: [0, 0, 3], state: "minecraft:dirt"},
        {pos: [1, 0, 0], state: "minecraft:dirt"},
        {pos: [1, 0, 1], state: "minecraft:clay"},
        {pos: [1, 0, 2], state: "minecraft:clay"},
        {pos: [1, 0, 3], state: "minecraft:dirt"},
        {pos: [2, 0, 0], state: "minecraft:dirt"},
        {pos: [2, 0, 1], state: "minecraft:clay"},
        {pos: [2, 0, 2], state: "minecraft:clay"},
        {pos: [2, 0, 3], state: "minecraft:dirt"},
        {pos: [3, 0, 0], state: "minecraft:dirt"},
        {pos: [3, 0, 1], state: "minecraft:clay"},
        {pos: [3, 0, 2], state: "minecraft:clay"},
        {pos: [3, 0, 3], state: "minecraft:dirt"},
        {pos: [4, 0, 0], state: "minecraft:dirt"},
        {pos: [4, 0, 1], state: "minecraft:dirt"},
        {pos: [4, 0, 2], state: "minecraft:dirt"},
        {pos: [4, 0, 3], state: "minecraft:dirt"},
        {pos: [0, 1, 0], state: "minecraft:dirt"},
        {pos: [0, 1, 1], state: "minecraft:clay"},
        {pos: [0, 1, 2], state: "minecraft:clay"},
        {pos: [0, 1, 3], state: "minecraft:dirt"},
        {pos: [1, 1, 0], state: "minecraft:clay"},
        {pos: [1, 1, 3], state: "minecraft:clay"},
        {pos: [2, 1, 0], state: "minecraft:clay"},
        {pos: [2, 1, 3], state: "minecraft:clay"},
        {pos: [3, 1, 0], state: "minecraft:clay"},
        {pos: [3, 1, 3], state: "minecraft:clay"},
        {pos: [4, 1, 0], state: "minecraft:dirt"},
        {pos: [4, 1, 1], state: "minecraft:clay"},
        {pos: [4, 1, 2], state: "minecraft:clay"},
        {pos: [4, 1, 3], state: "minecraft:dirt"},
        {pos: [0, 2, 0], state: "minecraft:dirt"},
        {pos: [0, 2, 1], state: "minecraft:clay"},
        {pos: [0, 2, 2], state: "minecraft:clay"},
        {pos: [0, 2, 3], state: "minecraft:dirt"},
        {pos: [1, 2, 0], state: "minecraft:clay"},
        {pos: [1, 2, 3], state: "minecraft:clay"},
        {pos: [2, 2, 0], state: "minecraft:clay"},
        {pos: [2, 2, 3], state: "minecraft:clay"},
        {pos: [3, 2, 0], state: "minecraft:clay"},
        {pos: [3, 2, 3], state: "minecraft:clay"},
        {pos: [4, 2, 0], state: "minecraft:dirt"},
        {pos: [4, 2, 1], state: "minecraft:clay"},
        {pos: [4, 2, 2], state: "minecraft:clay"},
        {pos: [4, 2, 3], state: "minecraft:dirt"},
        {pos: [0, 3, 0], state: "minecraft:dirt"},
        {pos: [0, 3, 1], state: "minecraft:dirt"},
        {pos: [0, 3, 2], state: "minecraft:dirt"},
        {pos: [0, 3, 3], state: "minecraft:dirt"},
        {pos: [1, 3, 0], state: "minecraft:dirt"},
        {pos: [1, 3, 1], state: "minecraft:clay"},
        {pos: [1, 3, 2], state: "minecraft:clay"},
        {pos: [1, 3, 3], state: "minecraft:dirt"},
        {pos: [2, 3, 0], state: "minecraft:dirt"},
        {pos: [2, 3, 1], state: "minecraft:clay"},
        {pos: [2, 3, 2], state: "minecraft:clay"},
        {pos: [2, 3, 3], state: "minecraft:dirt"},
        {pos: [3, 3, 0], state: "minecraft:dirt"},
        {pos: [3, 3, 1], state: "minecraft:clay"},
        {pos: [3, 3, 2], state: "minecraft:clay"},
        {pos: [3, 3, 3], state: "minecraft:dirt"},
        {pos: [4, 3, 0], state: "minecraft:dirt"},
        {pos: [4, 3, 1], state: "minecraft:dirt"},
        {pos: [4, 3, 2], state: "minecraft:dirt"},
        {pos: [4, 3, 3], state: "minecraft:dirt"}
    ],
    entities: [],
    palette: [
        "minecraft:dirt",
        "minecraft:clay"
    ]
}