{
    DataVersion: 3955,
    size: [5, 5, 5],
    data: [
        {pos: [0, 0, 0], state: "nuclearcraftneohaul:turbine_casing{nuclearcraftneohaul_frame:false}", nbt: {alternateComparator: 0b, id: "nuclearcraftneohaul:turbine_casing", isRedstonePowered: 0b, radiationLevel: 0.0d, redstoneControl: 0b, zcvase_payload: {multiblockData: {angVel: 0.0f, basePowerPerMB: 0.0d, bearingTension: 0.0d, bladeAngleArray: {float0: 45.0f, float1: 45.0f, float10: -45.0f, float11: -45.0f, float2: 45.0f, float3: -45.0f, float4: -45.0f, float5: -45.0f, float6: 45.0f, float7: 45.0f, float8: 45.0f, float9: -45.0f, length: 12}, bladeLength: 0, bladePosArray: {length: 12, pos0: [I; 13, -59, 7], pos1: [I; 13, -59, 8], pos10: [I; 13, -57, 8], pos11: [I; 13, -57, 9], pos2: [I; 13, -59, 9], pos3: [I; 12, -58, 7], pos4: [I; 12, -58, 8], pos5: [I; 12, -58, 9], pos6: [I; 14, -58, 7], pos7: [I; 14, -58, 8], pos8: [I; 14, -58, 9], pos9: [I; 13, -57, 7]}, computerActivated: 0b, conductivity: 0.0d, dynamoCoilCount: 7, dynamoCoilCountOpposite: 7, effectiveMaxLength: 24, energyStorage: {capacity: 2000000L, energy: 0L, maxTransfer: 2000000}, expansionLevels: {}, flowDir: -1, idealTotalExpansionLevel: 0.0d, isProcessing: 0b, isTurbineOn: 0b, logic: {}, logicID: "turbine", maxBladeExpansionCoefficient: 1.0d, maxStatorExpansionCoefficient: 4.9E-324d, minBladeExpansionCoefficient: 1.7976931348623157E308d, minStatorExpansionCoefficient: 1.0d, noBladeSets: 0, particleEffect: "cloud", particleSpeedMult: 0.04310344827586207d, power: 0.0d, powerBonus: 1.0d, rawBladeEfficiencies: {}, rawPower: 0.0d, recipeInputRate: 0, recipeInputRateFP: 0.0d, renderPosArray: {length: 15, vector0: {floatx: 2.0f, floaty: 0.0f, floatz: -1.0f}, vector1: {floatx: 2.0f, floaty: 0.0f, floatz: 0.0f}, vector10: {floatx: 2.0f, floaty: 2.0f, floatz: 0.0f}, vector11: {floatx: 2.0f, floaty: 2.0f, floatz: 1.0f}, vector12: {floatx: 2.0f, floaty: 1.0f, floatz: -1.0f}, vector13: {floatx: 2.0f, floaty: 1.0f, floatz: 0.0f}, vector14: {floatx: 2.0f, floaty: 1.0f, floatz: 1.0f}, vector2: {floatx: 2.0f, floaty: 0.0f, floatz: 1.0f}, vector3: {floatx: 1.0f, floaty: 1.0f, floatz: -1.0f}, vector4: {floatx: 1.0f, floaty: 1.0f, floatz: 0.0f}, vector5: {floatx: 1.0f, floaty: 1.0f, floatz: 1.0f}, vector6: {floatx: 3.0f, floaty: 1.0f, floatz: -1.0f}, vector7: {floatx: 3.0f, floaty: 1.0f, floatz: 0.0f}, vector8: {floatx: 3.0f, floaty: 1.0f, floatz: 1.0f}, vector9: {floatx: 2.0f, floaty: 2.0f, floatz: -1.0f}}, rotorAngle: 0.0f, rotorEfficiency: 0.0d, shaftVolume: 0, shaftWidth: 0, spinUpMultiplier: 1.0d, tanks0: {capacity: 125000}, tanks1: {capacity: 500000}, totalExpansionLevel: 1.0d}}, zcvase_version: -1}},
        {pos: [0, 0, 1], state: "nuclearcraftneohaul:turbine_casing{nuclearcraftneohaul_frame:false}", nbt: {alternateComparator: 0b, id: "nuclearcraftneohaul:turbine_casing", isRedstonePowered: 0b, radiationLevel: 0.0d, redstoneControl: 0b, zcvase_payload: {}, zcvase_version: -1}},
        {pos: [0, 0, 2], state: "nuclearcraftneohaul:turbine_casing{nuclearcraftneohaul_frame:false}", nbt: {alternateComparator: 0b, id: "nuclearcraftneohaul:turbine_casing", isRedstonePowered: 0b, radiationLevel: 0.0d, redstoneControl: 0b, zcvase_payload: {}, zcvase_version: -1}},
        {pos: [0, 0, 3], state: "nuclearcraftneohaul:turbine_casing{nuclearcraftneohaul_frame:false}", nbt: {alternateComparator: 0b, id: "nuclearcraftneohaul:turbine_casing", isRedstonePowered: 0b, radiationLevel: 0.0d, redstoneControl: 0b, zcvase_payload: {}, zcvase_version: -1}},
        {pos: [0, 0, 4], state: "nuclearcraftneohaul:turbine_casing{nuclearcraftneohaul_frame:false}", nbt: {alternateComparator: 0b, id: "nuclearcraftneohaul:turbine_casing", isRedstonePowered: 0b, radiationLevel: 0.0d, redstoneControl: 0b, zcvase_payload: {}, zcvase_version: -1}},
        {pos: [1, 0, 0], state: "nuclearcraftneohaul:turbine_casing{nuclearcraftneohaul_frame:false}", nbt: {alternateComparator: 0b, id: "nuclearcraftneohaul:turbine_casing", isRedstonePowered: 0b, radiationLevel: 0.0d, redstoneControl: 0b, zcvase_payload: {}, zcvase_version: -1}},
        {pos: [1, 0, 1], state: "nuclearcraftneohaul:turbine_glass{facings:none}", nbt: {alternateComparator: 0b, id: "nuclearcraftneohaul:turbine_glass", isRedstonePowered: 0b, radiationLevel: 0.0d, redstoneControl: 0b, zcvase_payload: {}, zcvase_version: -1}},
        {pos: [1, 0, 2], state: "nuclearcraftneohaul:turbine_glass{facings:none}", nbt: {alternateComparator: 0b, id: "nuclearcraftneohaul:turbine_glass", isRedstonePowered: 0b, radiationLevel: 0.0d, redstoneControl: 0b, zcvase_payload: {}, zcvase_version: -1}},
        {pos: [1, 0, 3], state: "nuclearcraftneohaul:turbine_glass{facings:none}", nbt: {alternateComparator: 0b, id: "nuclearcraftneohaul:turbine_glass", isRedstonePowered: 0b, radiationLevel: 0.0d, redstoneControl: 0b, zcvase_payload: {}, zcvase_version: -1}},
        {pos: [1, 0, 4], state: "nuclearcraftneohaul:turbine_casing{nuclearcraftneohaul_frame:false}", nbt: {alternateComparator: 0b, id: "nuclearcraftneohaul:turbine_casing", isRedstonePowered: 0b, radiationLevel: 0.0d, redstoneControl: 0b, zcvase_payload: {}, zcvase_version: -1}},
        {pos: [2, 0, 0], state: "nuclearcraftneohaul:turbine_casing{nuclearcraftneohaul_frame:false}", nbt: {alternateComparator: 0b, id: "nuclearcraftneohaul:turbine_casing", isRedstonePowered: 0b, radiationLevel: 0.0d, redstoneControl: 0b, zcvase_payload: {}, zcvase_version: -1}},
        {pos: [2, 0, 1], state: "nuclearcraftneohaul:turbine_glass{facings:none}", nbt: {alternateComparator: 0b, id: "nuclearcraftneohaul:turbine_glass", isRedstonePowered: 0b, radiationLevel: 0.0d, redstoneControl: 0b, zcvase_payload: {}, zcvase_version: -1}},
        {pos: [2, 0, 2], state: "nuclearcraftneohaul:turbine_glass{facings:none}", nbt: {alternateComparator: 0b, id: "nuclearcraftneohaul:turbine_glass", isRedstonePowered: 0b, radiationLevel: 0.0d, redstoneControl: 0b, zcvase_payload: {}, zcvase_version: -1}},
        {pos: [2, 0, 3], state: "nuclearcraftneohaul:turbine_glass{facings:none}", nbt: {alternateComparator: 0b, id: "nuclearcraftneohaul:turbine_glass", isRedstonePowered: 0b, radiationLevel: 0.0d, redstoneControl: 0b, zcvase_payload: {}, zcvase_version: -1}},
        {pos: [2, 0, 4], state: "nuclearcraftneohaul:turbine_casing{nuclearcraftneohaul_frame:false}", nbt: {alternateComparator: 0b, id: "nuclearcraftneohaul:turbine_casing", isRedstonePowered: 0b, radiationLevel: 0.0d, redstoneControl: 0b, zcvase_payload: {}, zcvase_version: -1}},
        {pos: [3, 0, 0], state: "nuclearcraftneohaul:turbine_casing{nuclearcraftneohaul_frame:false}", nbt: {alternateComparator: 0b, id: "nuclearcraftneohaul:turbine_casing", isRedstonePowered: 0b, radiationLevel: 0.0d, redstoneControl: 0b, zcvase_payload: {}, zcvase_version: -1}},
        {pos: [3, 0, 1], state: "nuclearcraftneohaul:turbine_glass{facings:none}", nbt: {alternateComparator: 0b, id: "nuclearcraftneohaul:turbine_glass", isRedstonePowered: 0b, radiationLevel: 0.0d, redstoneControl: 0b, zcvase_payload: {}, zcvase_version: -1}},
        {pos: [3, 0, 2], state: "nuclearcraftneohaul:turbine_glass{facings:none}", nbt: {alternateComparator: 0b, id: "nuclearcraftneohaul:turbine_glass", isRedstonePowered: 0b, radiationLevel: 0.0d, redstoneControl: 0b, zcvase_payload: {}, zcvase_version: -1}},
        {pos: [3, 0, 3], state: "nuclearcraftneohaul:turbine_glass{facings:none}", nbt: {alternateComparator: 0b, id: "nuclearcraftneohaul:turbine_glass", isRedstonePowered: 0b, radiationLevel: 0.0d, redstoneControl: 0b, zcvase_payload: {}, zcvase_version: -1}},
        {pos: [3, 0, 4], state: "nuclearcraftneohaul:turbine_casing{nuclearcraftneohaul_frame:false}", nbt: {alternateComparator: 0b, id: "nuclearcraftneohaul:turbine_casing", isRedstonePowered: 0b, radiationLevel: 0.0d, redstoneControl: 0b, zcvase_payload: {}, zcvase_version: -1}},
        {pos: [4, 0, 0], state: "nuclearcraftneohaul:turbine_casing{nuclearcraftneohaul_frame:false}", nbt: {alternateComparator: 0b, id: "nuclearcraftneohaul:turbine_casing", isRedstonePowered: 0b, radiationLevel: 0.0d, redstoneControl: 0b, zcvase_payload: {}, zcvase_version: -1}},
        {pos: [4, 0, 1], state: "nuclearcraftneohaul:turbine_casing{nuclearcraftneohaul_frame:false}", nbt: {alternateComparator: 0b, id: "nuclearcraftneohaul:turbine_casing", isRedstonePowered: 0b, radiationLevel: 0.0d, redstoneControl: 0b, zcvase_payload: {}, zcvase_version: -1}},
        {pos: [4, 0, 2], state: "nuclearcraftneohaul:turbine_casing{nuclearcraftneohaul_frame:false}", nbt: {alternateComparator: 0b, id: "nuclearcraftneohaul:turbine_casing", isRedstonePowered: 0b, radiationLevel: 0.0d, redstoneControl: 0b, zcvase_payload: {}, zcvase_version: -1}},
        {pos: [4, 0, 3], state: "nuclearcraftneohaul:turbine_casing{nuclearcraftneohaul_frame:false}", nbt: {alternateComparator: 0b, id: "nuclearcraftneohaul:turbine_casing", isRedstonePowered: 0b, radiationLevel: 0.0d, redstoneControl: 0b, zcvase_payload: {}, zcvase_version: -1}},
        {pos: [4, 0, 4], state: "nuclearcraftneohaul:turbine_casing{nuclearcraftneohaul_frame:false}", nbt: {alternateComparator: 0b, id: "nuclearcraftneohaul:turbine_casing", isRedstonePowered: 0b, radiationLevel: 0.0d, redstoneControl: 0b, zcvase_payload: {}, zcvase_version: -1}},
        {pos: [0, 1, 0], state: "nuclearcraftneohaul:turbine_casing{nuclearcraftneohaul_frame:false}", nbt: {alternateComparator: 0b, id: "nuclearcraftneohaul:turbine_casing", isRedstonePowered: 0b, radiationLevel: 0.0d, redstoneControl: 0b, zcvase_payload: {}, zcvase_version: -1}},
        {pos: [0, 1, 1], state: "nuclearcraftneohaul:turbine_glass{facings:none}", nbt: {alternateComparator: 0b, id: "nuclearcraftneohaul:turbine_glass", isRedstonePowered: 0b, radiationLevel: 0.0d, redstoneControl: 0b, zcvase_payload: {}, zcvase_version: -1}},
        {pos: [0, 1, 2], state: "minecraft:stone"},
        {pos: [0, 1, 3], state: "nuclearcraftneohaul:turbine_glass{facings:none}", nbt: {alternateComparator: 0b, id: "nuclearcraftneohaul:turbine_glass", isRedstonePowered: 0b, radiationLevel: 0.0d, redstoneControl: 0b, zcvase_payload: {}, zcvase_version: -1}},
        {pos: [0, 1, 4], state: "nuclearcraftneohaul:turbine_casing{nuclearcraftneohaul_frame:false}", nbt: {alternateComparator: 0b, id: "nuclearcraftneohaul:turbine_casing", isRedstonePowered: 0b, radiationLevel: 0.0d, redstoneControl: 0b, zcvase_payload: {}, zcvase_version: -1}},
        {pos: [1, 1, 0], state: "nuclearcraftneohaul:beryllium_turbine_dynamo_coil", nbt: {alternateComparator: 0b, energyConnections0: 3, energyConnections1: 3, energyConnections2: 1, energyConnections3: 1, energyConnections4: 3, energyConnections5: 3, id: "nuclearcraftneohaul:turbine_dynamo", isInValidPosition: 0b, isRedstonePowered: 0b, radiationLevel: 0.0d, redstoneControl: 0b, zcvase_payload: {}, zcvase_version: -1}},
        {pos: [1, 1, 4], state: "nuclearcraftneohaul:beryllium_turbine_dynamo_coil", nbt: {alternateComparator: 0b, energyConnections0: 3, energyConnections1: 3, energyConnections2: 1, energyConnections3: 1, energyConnections4: 3, energyConnections5: 3, id: "nuclearcraftneohaul:turbine_dynamo", isInValidPosition: 0b, isRedstonePowered: 0b, radiationLevel: 0.0d, redstoneControl: 0b, zcvase_payload: {}, zcvase_version: -1}},
        {pos: [2, 1, 0], state: "nuclearcraftneohaul:magnesium_turbine_dynamo_coil", nbt: {alternateComparator: 0b, energyConnections0: 3, energyConnections1: 3, energyConnections2: 1, energyConnections3: 1, energyConnections4: 3, energyConnections5: 3, id: "nuclearcraftneohaul:turbine_dynamo", isInValidPosition: 0b, isRedstonePowered: 0b, radiationLevel: 0.0d, redstoneControl: 0b, zcvase_payload: {}, zcvase_version: -1}},
        {pos: [2, 1, 1], state: "nuclearcraftneohaul:steel_turbine_rotor_blade{dir:y}", nbt: {alternateComparator: 0b, bladeDir: 2, id: "nuclearcraftneohaul:turbine_rotor_blade", isRedstonePowered: 0b, radiationLevel: 0.0d, redstoneControl: 0b, zcvase_payload: {}, zcvase_version: -1}},
        {pos: [2, 1, 2], state: "nuclearcraftneohaul:steel_turbine_rotor_blade{dir:y}", nbt: {alternateComparator: 0b, bladeDir: 2, id: "nuclearcraftneohaul:turbine_rotor_blade", isRedstonePowered: 0b, radiationLevel: 0.0d, redstoneControl: 0b, zcvase_payload: {}, zcvase_version: -1}},
        {pos: [2, 1, 3], state: "nuclearcraftneohaul:steel_turbine_rotor_blade{dir:y}", nbt: {alternateComparator: 0b, bladeDir: 2, id: "nuclearcraftneohaul:turbine_rotor_blade", isRedstonePowered: 0b, radiationLevel: 0.0d, redstoneControl: 0b, zcvase_payload: {}, zcvase_version: -1}},
        {pos: [2, 1, 4], state: "nuclearcraftneohaul:magnesium_turbine_dynamo_coil", nbt: {alternateComparator: 0b, energyConnections0: 3, energyConnections1: 3, energyConnections2: 1, energyConnections3: 1, energyConnections4: 3, energyConnections5: 3, id: "nuclearcraftneohaul:turbine_dynamo", isInValidPosition: 0b, isRedstonePowered: 0b, radiationLevel: 0.0d, redstoneControl: 0b, zcvase_payload: {}, zcvase_version: -1}},
        {pos: [3, 1, 0], state: "nuclearcraftneohaul:turbine_inlet{facing:north}", nbt: {alternateComparator: 0b, fluidConnection0: {sorption0: 0}, fluidConnection1: {sorption0: 0}, fluidConnection2: {sorption0: 0}, fluidConnection3: {sorption0: 0}, fluidConnection4: {sorption0: 0}, fluidConnection5: {sorption0: 0}, id: "nuclearcraftneohaul:turbine_inlet", isRedstonePowered: 0b, radiationLevel: 0.0d, redstoneControl: 0b, zcvase_payload: {}, zcvase_version: -1}},
        {pos: [3, 1, 4], state: "nuclearcraftneohaul:turbine_outlet{facing:south}", nbt: {alternateComparator: 0b, fluidConnection0: {sorption0: 3}, fluidConnection1: {sorption0: 3}, fluidConnection2: {sorption0: 3}, fluidConnection3: {sorption0: 1}, fluidConnection4: {sorption0: 3}, fluidConnection5: {sorption0: 3}, id: "nuclearcraftneohaul:turbine_outlet", isRedstonePowered: 0b, radiationLevel: 0.0d, redstoneControl: 0b, zcvase_payload: {}, zcvase_version: -1}},
        {pos: [4, 1, 0], state: "nuclearcraftneohaul:turbine_casing{nuclearcraftneohaul_frame:false}", nbt: {alternateComparator: 0b, id: "nuclearcraftneohaul:turbine_casing", isRedstonePowered: 0b, radiationLevel: 0.0d, redstoneControl: 0b, zcvase_payload: {}, zcvase_version: -1}},
        {pos: [4, 1, 1], state: "nuclearcraftneohaul:turbine_glass{facings:none}", nbt: {alternateComparator: 0b, id: "nuclearcraftneohaul:turbine_glass", isRedstonePowered: 0b, radiationLevel: 0.0d, redstoneControl: 0b, zcvase_payload: {}, zcvase_version: -1}},
        {pos: [4, 1, 2], state: "nuclearcraftneohaul:turbine_glass{facings:none}", nbt: {alternateComparator: 0b, id: "nuclearcraftneohaul:turbine_glass", isRedstonePowered: 0b, radiationLevel: 0.0d, redstoneControl: 0b, zcvase_payload: {}, zcvase_version: -1}},
        {pos: [4, 1, 3], state: "nuclearcraftneohaul:turbine_glass{facings:none}", nbt: {alternateComparator: 0b, id: "nuclearcraftneohaul:turbine_glass", isRedstonePowered: 0b, radiationLevel: 0.0d, redstoneControl: 0b, zcvase_payload: {}, zcvase_version: -1}},
        {pos: [4, 1, 4], state: "nuclearcraftneohaul:turbine_casing{nuclearcraftneohaul_frame:false}", nbt: {alternateComparator: 0b, id: "nuclearcraftneohaul:turbine_casing", isRedstonePowered: 0b, radiationLevel: 0.0d, redstoneControl: 0b, zcvase_payload: {}, zcvase_version: -1}},
        {pos: [0, 2, 0], state: "nuclearcraftneohaul:turbine_casing{nuclearcraftneohaul_frame:false}", nbt: {alternateComparator: 0b, id: "nuclearcraftneohaul:turbine_casing", isRedstonePowered: 0b, radiationLevel: 0.0d, redstoneControl: 0b, zcvase_payload: {}, zcvase_version: -1}},
        {pos: [0, 2, 1], state: "nuclearcraftneohaul:turbine_glass{facings:none}", nbt: {alternateComparator: 0b, id: "nuclearcraftneohaul:turbine_glass", isRedstonePowered: 0b, radiationLevel: 0.0d, redstoneControl: 0b, zcvase_payload: {}, zcvase_version: -1}},
        {pos: [0, 2, 2], state: "nuclearcraftneohaul:turbine_glass{facings:none}", nbt: {alternateComparator: 0b, id: "nuclearcraftneohaul:turbine_glass", isRedstonePowered: 0b, radiationLevel: 0.0d, redstoneControl: 0b, zcvase_payload: {}, zcvase_version: -1}},
        {pos: [0, 2, 3], state: "nuclearcraftneohaul:turbine_glass{facings:none}", nbt: {alternateComparator: 0b, id: "nuclearcraftneohaul:turbine_glass", isRedstonePowered: 0b, radiationLevel: 0.0d, redstoneControl: 0b, zcvase_payload: {}, zcvase_version: -1}},
        {pos: [0, 2, 4], state: "nuclearcraftneohaul:turbine_casing{nuclearcraftneohaul_frame:false}", nbt: {alternateComparator: 0b, id: "nuclearcraftneohaul:turbine_casing", isRedstonePowered: 0b, radiationLevel: 0.0d, redstoneControl: 0b, zcvase_payload: {}, zcvase_version: -1}},
        {pos: [1, 2, 0], state: "nuclearcraftneohaul:magnesium_turbine_dynamo_coil", nbt: {alternateComparator: 0b, energyConnections0: 3, energyConnections1: 3, energyConnections2: 1, energyConnections3: 1, energyConnections4: 3, energyConnections5: 3, id: "nuclearcraftneohaul:turbine_dynamo", isInValidPosition: 0b, isRedstonePowered: 0b, radiationLevel: 0.0d, redstoneControl: 0b, zcvase_payload: {}, zcvase_version: -1}},
        {pos: [1, 2, 1], state: "nuclearcraftneohaul:steel_turbine_rotor_blade{dir:x}", nbt: {alternateComparator: 0b, bladeDir: 1, id: "nuclearcraftneohaul:turbine_rotor_blade", isRedstonePowered: 0b, radiationLevel: 0.0d, redstoneControl: 0b, zcvase_payload: {}, zcvase_version: -1}},
        {pos: [1, 2, 2], state: "nuclearcraftneohaul:steel_turbine_rotor_blade{dir:x}", nbt: {alternateComparator: 0b, bladeDir: 1, id: "nuclearcraftneohaul:turbine_rotor_blade", isRedstonePowered: 0b, radiationLevel: 0.0d, redstoneControl: 0b, zcvase_payload: {}, zcvase_version: -1}},
        {pos: [1, 2, 3], state: "nuclearcraftneohaul:steel_turbine_rotor_blade{dir:x}", nbt: {alternateComparator: 0b, bladeDir: 1, id: "nuclearcraftneohaul:turbine_rotor_blade", isRedstonePowered: 0b, radiationLevel: 0.0d, redstoneControl: 0b, zcvase_payload: {}, zcvase_version: -1}},
        {pos: [1, 2, 4], state: "nuclearcraftneohaul:magnesium_turbine_dynamo_coil", nbt: {alternateComparator: 0b, energyConnections0: 3, energyConnections1: 3, energyConnections2: 1, energyConnections3: 1, energyConnections4: 3, energyConnections5: 3, id: "nuclearcraftneohaul:turbine_dynamo", isInValidPosition: 0b, isRedstonePowered: 0b, radiationLevel: 0.0d, redstoneControl: 0b, zcvase_payload: {}, zcvase_version: -1}},
        {pos: [2, 2, 0], state: "nuclearcraftneohaul:turbine_rotor_bearing", nbt: {alternateComparator: 0b, id: "nuclearcraftneohaul:turbine_rotor_bearing", isRedstonePowered: 0b, radiationLevel: 0.0d, redstoneControl: 0b, zcvase_payload: {}, zcvase_version: -1}},
        {pos: [2, 2, 1], state: "nuclearcraftneohaul:turbine_rotor_shaft{dir:z}", nbt: {alternateComparator: 0b, id: "nuclearcraftneohaul:turbine_rotor_shaft", isRedstonePowered: 0b, radiationLevel: 0.0d, redstoneControl: 0b, zcvase_payload: {}, zcvase_version: -1}},
        {pos: [2, 2, 2], state: "nuclearcraftneohaul:turbine_rotor_shaft{dir:z}", nbt: {alternateComparator: 0b, id: "nuclearcraftneohaul:turbine_rotor_shaft", isRedstonePowered: 0b, radiationLevel: 0.0d, redstoneControl: 0b, zcvase_payload: {}, zcvase_version: -1}},
        {pos: [2, 2, 3], state: "nuclearcraftneohaul:turbine_rotor_shaft{dir:z}", nbt: {alternateComparator: 0b, id: "nuclearcraftneohaul:turbine_rotor_shaft", isRedstonePowered: 0b, radiationLevel: 0.0d, redstoneControl: 0b, zcvase_payload: {}, zcvase_version: -1}},
        {pos: [2, 2, 4], state: "nuclearcraftneohaul:turbine_rotor_bearing", nbt: {alternateComparator: 0b, id: "nuclearcraftneohaul:turbine_rotor_bearing", isRedstonePowered: 0b, radiationLevel: 0.0d, redstoneControl: 0b, zcvase_payload: {}, zcvase_version: -1}},
        {pos: [3, 2, 0], state: "nuclearcraftneohaul:magnesium_turbine_dynamo_coil", nbt: {alternateComparator: 0b, energyConnections0: 3, energyConnections1: 3, energyConnections2: 1, energyConnections3: 1, energyConnections4: 3, energyConnections5: 3, id: "nuclearcraftneohaul:turbine_dynamo", isInValidPosition: 0b, isRedstonePowered: 0b, radiationLevel: 0.0d, redstoneControl: 0b, zcvase_payload: {}, zcvase_version: -1}},
        {pos: [3, 2, 1], state: "nuclearcraftneohaul:steel_turbine_rotor_blade{dir:x}", nbt: {alternateComparator: 0b, bladeDir: 1, id: "nuclearcraftneohaul:turbine_rotor_blade", isRedstonePowered: 0b, radiationLevel: 0.0d, redstoneControl: 0b, zcvase_payload: {}, zcvase_version: -1}},
        {pos: [3, 2, 2], state: "nuclearcraftneohaul:steel_turbine_rotor_blade{dir:x}", nbt: {alternateComparator: 0b, bladeDir: 1, id: "nuclearcraftneohaul:turbine_rotor_blade", isRedstonePowered: 0b, radiationLevel: 0.0d, redstoneControl: 0b, zcvase_payload: {}, zcvase_version: -1}},
        {pos: [3, 2, 3], state: "nuclearcraftneohaul:steel_turbine_rotor_blade{dir:x}", nbt: {alternateComparator: 0b, bladeDir: 1, id: "nuclearcraftneohaul:turbine_rotor_blade", isRedstonePowered: 0b, radiationLevel: 0.0d, redstoneControl: 0b, zcvase_payload: {}, zcvase_version: -1}},
        {pos: [3, 2, 4], state: "nuclearcraftneohaul:magnesium_turbine_dynamo_coil", nbt: {alternateComparator: 0b, energyConnections0: 3, energyConnections1: 3, energyConnections2: 1, energyConnections3: 1, energyConnections4: 3, energyConnections5: 3, id: "nuclearcraftneohaul:turbine_dynamo", isInValidPosition: 0b, isRedstonePowered: 0b, radiationLevel: 0.0d, redstoneControl: 0b, zcvase_payload: {}, zcvase_version: -1}},
        {pos: [4, 2, 0], state: "nuclearcraftneohaul:turbine_casing{nuclearcraftneohaul_frame:false}", nbt: {alternateComparator: 0b, id: "nuclearcraftneohaul:turbine_casing", isRedstonePowered: 0b, radiationLevel: 0.0d, redstoneControl: 0b, zcvase_payload: {}, zcvase_version: -1}},
        {pos: [4, 2, 1], state: "nuclearcraftneohaul:turbine_glass{facings:none}", nbt: {alternateComparator: 0b, id: "nuclearcraftneohaul:turbine_glass", isRedstonePowered: 0b, radiationLevel: 0.0d, redstoneControl: 0b, zcvase_payload: {}, zcvase_version: -1}},
        {pos: [4, 2, 2], state: "nuclearcraftneohaul:turbine_glass{facings:none}", nbt: {alternateComparator: 0b, id: "nuclearcraftneohaul:turbine_glass", isRedstonePowered: 0b, radiationLevel: 0.0d, redstoneControl: 0b, zcvase_payload: {}, zcvase_version: -1}},
        {pos: [4, 2, 3], state: "nuclearcraftneohaul:turbine_glass{facings:none}", nbt: {alternateComparator: 0b, id: "nuclearcraftneohaul:turbine_glass", isRedstonePowered: 0b, radiationLevel: 0.0d, redstoneControl: 0b, zcvase_payload: {}, zcvase_version: -1}},
        {pos: [4, 2, 4], state: "nuclearcraftneohaul:turbine_casing{nuclearcraftneohaul_frame:false}", nbt: {alternateComparator: 0b, id: "nuclearcraftneohaul:turbine_casing", isRedstonePowered: 0b, radiationLevel: 0.0d, redstoneControl: 0b, zcvase_payload: {}, zcvase_version: -1}},
        {pos: [0, 3, 0], state: "nuclearcraftneohaul:turbine_casing{nuclearcraftneohaul_frame:false}", nbt: {alternateComparator: 0b, id: "nuclearcraftneohaul:turbine_casing", isRedstonePowered: 0b, radiationLevel: 0.0d, redstoneControl: 0b, zcvase_payload: {}, zcvase_version: -1}},
        {pos: [0, 3, 1], state: "nuclearcraftneohaul:turbine_glass{facings:none}", nbt: {alternateComparator: 0b, id: "nuclearcraftneohaul:turbine_glass", isRedstonePowered: 0b, radiationLevel: 0.0d, redstoneControl: 0b, zcvase_payload: {}, zcvase_version: -1}},
        {pos: [0, 3, 2], state: "nuclearcraftneohaul:turbine_glass{facings:none}", nbt: {alternateComparator: 0b, id: "nuclearcraftneohaul:turbine_glass", isRedstonePowered: 0b, radiationLevel: 0.0d, redstoneControl: 0b, zcvase_payload: {}, zcvase_version: -1}},
        {pos: [0, 3, 3], state: "nuclearcraftneohaul:turbine_glass{facings:none}", nbt: {alternateComparator: 0b, id: "nuclearcraftneohaul:turbine_glass", isRedstonePowered: 0b, radiationLevel: 0.0d, redstoneControl: 0b, zcvase_payload: {}, zcvase_version: -1}},
        {pos: [0, 3, 4], state: "nuclearcraftneohaul:turbine_casing{nuclearcraftneohaul_frame:false}", nbt: {alternateComparator: 0b, id: "nuclearcraftneohaul:turbine_casing", isRedstonePowered: 0b, radiationLevel: 0.0d, redstoneControl: 0b, zcvase_payload: {}, zcvase_version: -1}},
        {pos: [1, 3, 0], state: "nuclearcraftneohaul:beryllium_turbine_dynamo_coil", nbt: {alternateComparator: 0b, energyConnections0: 3, energyConnections1: 3, energyConnections2: 1, energyConnections3: 1, energyConnections4: 3, energyConnections5: 3, id: "nuclearcraftneohaul:turbine_dynamo", isInValidPosition: 0b, isRedstonePowered: 0b, radiationLevel: 0.0d, redstoneControl: 0b, zcvase_payload: {}, zcvase_version: -1}},
        {pos: [1, 3, 4], state: "nuclearcraftneohaul:beryllium_turbine_dynamo_coil", nbt: {alternateComparator: 0b, energyConnections0: 3, energyConnections1: 3, energyConnections2: 1, energyConnections3: 1, energyConnections4: 3, energyConnections5: 3, id: "nuclearcraftneohaul:turbine_dynamo", isInValidPosition: 0b, isRedstonePowered: 0b, radiationLevel: 0.0d, redstoneControl: 0b, zcvase_payload: {}, zcvase_version: -1}},
        {pos: [2, 3, 0], state: "nuclearcraftneohaul:magnesium_turbine_dynamo_coil", nbt: {alternateComparator: 0b, energyConnections0: 3, energyConnections1: 3, energyConnections2: 1, energyConnections3: 1, energyConnections4: 3, energyConnections5: 3, id: "nuclearcraftneohaul:turbine_dynamo", isInValidPosition: 0b, isRedstonePowered: 0b, radiationLevel: 0.0d, redstoneControl: 0b, zcvase_payload: {}, zcvase_version: -1}},
        {pos: [2, 3, 1], state: "nuclearcraftneohaul:steel_turbine_rotor_blade{dir:y}", nbt: {alternateComparator: 0b, bladeDir: 2, id: "nuclearcraftneohaul:turbine_rotor_blade", isRedstonePowered: 0b, radiationLevel: 0.0d, redstoneControl: 0b, zcvase_payload: {}, zcvase_version: -1}},
        {pos: [2, 3, 2], state: "nuclearcraftneohaul:steel_turbine_rotor_blade{dir:y}", nbt: {alternateComparator: 0b, bladeDir: 2, id: "nuclearcraftneohaul:turbine_rotor_blade", isRedstonePowered: 0b, radiationLevel: 0.0d, redstoneControl: 0b, zcvase_payload: {}, zcvase_version: -1}},
        {pos: [2, 3, 3], state: "nuclearcraftneohaul:steel_turbine_rotor_blade{dir:y}", nbt: {alternateComparator: 0b, bladeDir: 2, id: "nuclearcraftneohaul:turbine_rotor_blade", isRedstonePowered: 0b, radiationLevel: 0.0d, redstoneControl: 0b, zcvase_payload: {}, zcvase_version: -1}},
        {pos: [2, 3, 4], state: "nuclearcraftneohaul:magnesium_turbine_dynamo_coil", nbt: {alternateComparator: 0b, energyConnections0: 3, energyConnections1: 3, energyConnections2: 1, energyConnections3: 1, energyConnections4: 3, energyConnections5: 3, id: "nuclearcraftneohaul:turbine_dynamo", isInValidPosition: 0b, isRedstonePowered: 0b, radiationLevel: 0.0d, redstoneControl: 0b, zcvase_payload: {}, zcvase_version: -1}},
        {pos: [3, 3, 0], state: "nuclearcraftneohaul:beryllium_turbine_dynamo_coil", nbt: {alternateComparator: 0b, energyConnections0: 3, energyConnections1: 3, energyConnections2: 1, energyConnections3: 1, energyConnections4: 3, energyConnections5: 3, id: "nuclearcraftneohaul:turbine_dynamo", isInValidPosition: 0b, isRedstonePowered: 0b, radiationLevel: 0.0d, redstoneControl: 0b, zcvase_payload: {}, zcvase_version: -1}},
        {pos: [3, 3, 4], state: "nuclearcraftneohaul:beryllium_turbine_dynamo_coil", nbt: {alternateComparator: 0b, energyConnections0: 3, energyConnections1: 3, energyConnections2: 1, energyConnections3: 1, energyConnections4: 3, energyConnections5: 3, id: "nuclearcraftneohaul:turbine_dynamo", isInValidPosition: 0b, isRedstonePowered: 0b, radiationLevel: 0.0d, redstoneControl: 0b, zcvase_payload: {}, zcvase_version: -1}},
        {pos: [4, 3, 0], state: "nuclearcraftneohaul:turbine_casing{nuclearcraftneohaul_frame:false}", nbt: {alternateComparator: 0b, id: "nuclearcraftneohaul:turbine_casing", isRedstonePowered: 0b, radiationLevel: 0.0d, redstoneControl: 0b, zcvase_payload: {}, zcvase_version: -1}},
        {pos: [4, 3, 1], state: "nuclearcraftneohaul:turbine_glass{facings:none}", nbt: {alternateComparator: 0b, id: "nuclearcraftneohaul:turbine_glass", isRedstonePowered: 0b, radiationLevel: 0.0d, redstoneControl: 0b, zcvase_payload: {}, zcvase_version: -1}},
        {pos: [4, 3, 2], state: "nuclearcraftneohaul:turbine_glass{facings:none}", nbt: {alternateComparator: 0b, id: "nuclearcraftneohaul:turbine_glass", isRedstonePowered: 0b, radiationLevel: 0.0d, redstoneControl: 0b, zcvase_payload: {}, zcvase_version: -1}},
        {pos: [4, 3, 3], state: "nuclearcraftneohaul:turbine_glass{facings:none}", nbt: {alternateComparator: 0b, id: "nuclearcraftneohaul:turbine_glass", isRedstonePowered: 0b, radiationLevel: 0.0d, redstoneControl: 0b, zcvase_payload: {}, zcvase_version: -1}},
        {pos: [4, 3, 4], state: "nuclearcraftneohaul:turbine_casing{nuclearcraftneohaul_frame:false}", nbt: {alternateComparator: 0b, id: "nuclearcraftneohaul:turbine_casing", isRedstonePowered: 0b, radiationLevel: 0.0d, redstoneControl: 0b, zcvase_payload: {}, zcvase_version: -1}},
        {pos: [0, 4, 0], state: "nuclearcraftneohaul:turbine_casing{nuclearcraftneohaul_frame:false}", nbt: {alternateComparator: 0b, id: "nuclearcraftneohaul:turbine_casing", isRedstonePowered: 0b, radiationLevel: 0.0d, redstoneControl: 0b, zcvase_payload: {}, zcvase_version: -1}},
        {pos: [0, 4, 1], state: "nuclearcraftneohaul:turbine_casing{nuclearcraftneohaul_frame:false}", nbt: {alternateComparator: 0b, id: "nuclearcraftneohaul:turbine_casing", isRedstonePowered: 0b, radiationLevel: 0.0d, redstoneControl: 0b, zcvase_payload: {}, zcvase_version: -1}},
        {pos: [0, 4, 2], state: "nuclearcraftneohaul:turbine_casing{nuclearcraftneohaul_frame:false}", nbt: {alternateComparator: 0b, id: "nuclearcraftneohaul:turbine_casing", isRedstonePowered: 0b, radiationLevel: 0.0d, redstoneControl: 0b, zcvase_payload: {}, zcvase_version: -1}},
        {pos: [0, 4, 3], state: "nuclearcraftneohaul:turbine_casing{nuclearcraftneohaul_frame:false}", nbt: {alternateComparator: 0b, id: "nuclearcraftneohaul:turbine_casing", isRedstonePowered: 0b, radiationLevel: 0.0d, redstoneControl: 0b, zcvase_payload: {}, zcvase_version: -1}},
        {pos: [0, 4, 4], state: "nuclearcraftneohaul:turbine_casing{nuclearcraftneohaul_frame:false}", nbt: {alternateComparator: 0b, id: "nuclearcraftneohaul:turbine_casing", isRedstonePowered: 0b, radiationLevel: 0.0d, redstoneControl: 0b, zcvase_payload: {}, zcvase_version: -1}},
        {pos: [1, 4, 0], state: "nuclearcraftneohaul:turbine_casing{nuclearcraftneohaul_frame:false}", nbt: {alternateComparator: 0b, id: "nuclearcraftneohaul:turbine_casing", isRedstonePowered: 0b, radiationLevel: 0.0d, redstoneControl: 0b, zcvase_payload: {}, zcvase_version: -1}},
        {pos: [1, 4, 1], state: "nuclearcraftneohaul:turbine_glass{facings:none}", nbt: {alternateComparator: 0b, id: "nuclearcraftneohaul:turbine_glass", isRedstonePowered: 0b, radiationLevel: 0.0d, redstoneControl: 0b, zcvase_payload: {}, zcvase_version: -1}},
        {pos: [1, 4, 2], state: "nuclearcraftneohaul:turbine_glass{facings:none}", nbt: {alternateComparator: 0b, id: "nuclearcraftneohaul:turbine_glass", isRedstonePowered: 0b, radiationLevel: 0.0d, redstoneControl: 0b, zcvase_payload: {}, zcvase_version: -1}},
        {pos: [1, 4, 3], state: "nuclearcraftneohaul:turbine_glass{facings:none}", nbt: {alternateComparator: 0b, id: "nuclearcraftneohaul:turbine_glass", isRedstonePowered: 0b, radiationLevel: 0.0d, redstoneControl: 0b, zcvase_payload: {}, zcvase_version: -1}},
        {pos: [1, 4, 4], state: "nuclearcraftneohaul:turbine_casing{nuclearcraftneohaul_frame:false}", nbt: {alternateComparator: 0b, id: "nuclearcraftneohaul:turbine_casing", isRedstonePowered: 0b, radiationLevel: 0.0d, redstoneControl: 0b, zcvase_payload: {}, zcvase_version: -1}},
        {pos: [2, 4, 0], state: "nuclearcraftneohaul:turbine_casing{nuclearcraftneohaul_frame:false}", nbt: {alternateComparator: 0b, id: "nuclearcraftneohaul:turbine_casing", isRedstonePowered: 0b, radiationLevel: 0.0d, redstoneControl: 0b, zcvase_payload: {}, zcvase_version: -1}},
        {pos: [2, 4, 1], state: "nuclearcraftneohaul:turbine_glass{facings:none}", nbt: {alternateComparator: 0b, id: "nuclearcraftneohaul:turbine_glass", isRedstonePowered: 0b, radiationLevel: 0.0d, redstoneControl: 0b, zcvase_payload: {}, zcvase_version: -1}},
        {pos: [2, 4, 2], state: "nuclearcraftneohaul:turbine_glass{facings:none}", nbt: {alternateComparator: 0b, id: "nuclearcraftneohaul:turbine_glass", isRedstonePowered: 0b, radiationLevel: 0.0d, redstoneControl: 0b, zcvase_payload: {}, zcvase_version: -1}},
        {pos: [2, 4, 3], state: "nuclearcraftneohaul:turbine_glass{facings:none}", nbt: {alternateComparator: 0b, id: "nuclearcraftneohaul:turbine_glass", isRedstonePowered: 0b, radiationLevel: 0.0d, redstoneControl: 0b, zcvase_payload: {}, zcvase_version: -1}},
        {pos: [2, 4, 4], state: "nuclearcraftneohaul:turbine_casing{nuclearcraftneohaul_frame:false}", nbt: {alternateComparator: 0b, id: "nuclearcraftneohaul:turbine_casing", isRedstonePowered: 0b, radiationLevel: 0.0d, redstoneControl: 0b, zcvase_payload: {}, zcvase_version: -1}},
        {pos: [3, 4, 0], state: "nuclearcraftneohaul:turbine_casing{nuclearcraftneohaul_frame:false}", nbt: {alternateComparator: 0b, id: "nuclearcraftneohaul:turbine_casing", isRedstonePowered: 0b, radiationLevel: 0.0d, redstoneControl: 0b, zcvase_payload: {}, zcvase_version: -1}},
        {pos: [3, 4, 1], state: "nuclearcraftneohaul:turbine_glass{facings:none}", nbt: {alternateComparator: 0b, id: "nuclearcraftneohaul:turbine_glass", isRedstonePowered: 0b, radiationLevel: 0.0d, redstoneControl: 0b, zcvase_payload: {}, zcvase_version: -1}},
        {pos: [3, 4, 2], state: "nuclearcraftneohaul:turbine_glass{facings:none}", nbt: {alternateComparator: 0b, id: "nuclearcraftneohaul:turbine_glass", isRedstonePowered: 0b, radiationLevel: 0.0d, redstoneControl: 0b, zcvase_payload: {}, zcvase_version: -1}},
        {pos: [3, 4, 3], state: "nuclearcraftneohaul:turbine_glass{facings:none}", nbt: {alternateComparator: 0b, id: "nuclearcraftneohaul:turbine_glass", isRedstonePowered: 0b, radiationLevel: 0.0d, redstoneControl: 0b, zcvase_payload: {}, zcvase_version: -1}},
        {pos: [3, 4, 4], state: "nuclearcraftneohaul:turbine_casing{nuclearcraftneohaul_frame:false}", nbt: {alternateComparator: 0b, id: "nuclearcraftneohaul:turbine_casing", isRedstonePowered: 0b, radiationLevel: 0.0d, redstoneControl: 0b, zcvase_payload: {}, zcvase_version: -1}},
        {pos: [4, 4, 0], state: "nuclearcraftneohaul:turbine_casing{nuclearcraftneohaul_frame:false}", nbt: {alternateComparator: 0b, id: "nuclearcraftneohaul:turbine_casing", isRedstonePowered: 0b, radiationLevel: 0.0d, redstoneControl: 0b, zcvase_payload: {}, zcvase_version: -1}},
        {pos: [4, 4, 1], state: "nuclearcraftneohaul:turbine_casing{nuclearcraftneohaul_frame:false}", nbt: {alternateComparator: 0b, id: "nuclearcraftneohaul:turbine_casing", isRedstonePowered: 0b, radiationLevel: 0.0d, redstoneControl: 0b, zcvase_payload: {}, zcvase_version: -1}},
        {pos: [4, 4, 2], state: "nuclearcraftneohaul:turbine_casing{nuclearcraftneohaul_frame:false}", nbt: {alternateComparator: 0b, id: "nuclearcraftneohaul:turbine_casing", isRedstonePowered: 0b, radiationLevel: 0.0d, redstoneControl: 0b, zcvase_payload: {}, zcvase_version: -1}},
        {pos: [4, 4, 3], state: "nuclearcraftneohaul:turbine_casing{nuclearcraftneohaul_frame:false}", nbt: {alternateComparator: 0b, id: "nuclearcraftneohaul:turbine_casing", isRedstonePowered: 0b, radiationLevel: 0.0d, redstoneControl: 0b, zcvase_payload: {}, zcvase_version: -1}},
        {pos: [4, 4, 4], state: "nuclearcraftneohaul:turbine_casing{nuclearcraftneohaul_frame:false}", nbt: {alternateComparator: 0b, id: "nuclearcraftneohaul:turbine_casing", isRedstonePowered: 0b, radiationLevel: 0.0d, redstoneControl: 0b, zcvase_payload: {}, zcvase_version: -1}}
    ],
    entities: [],
    palette: [
        "minecraft:stone",
        "nuclearcraftneohaul:turbine_casing{nuclearcraftneohaul_frame:false}",
        "nuclearcraftneohaul:turbine_glass{facings:none}",
        "nuclearcraftneohaul:beryllium_turbine_dynamo_coil",
        "nuclearcraftneohaul:magnesium_turbine_dynamo_coil",
        "nuclearcraftneohaul:steel_turbine_rotor_blade{dir:y}",
        "nuclearcraftneohaul:turbine_inlet{facing:north}",
        "nuclearcraftneohaul:turbine_outlet{facing:south}",
        "nuclearcraftneohaul:steel_turbine_rotor_blade{dir:x}",
        "nuclearcraftneohaul:turbine_rotor_bearing",
        "nuclearcraftneohaul:turbine_rotor_shaft{dir:z}"
    ]
}