{
    DataVersion: 3955,
    size: [7, 4, 6],
    data: [
        {pos: [2, 0, 3], state: "nuclearcraftneohaul:turbine_outlet{facing:west}", nbt: {alternateComparator: 0b, fluidConnection0: {sorption0: 1}, fluidConnection1: {sorption0: 1}, fluidConnection2: {sorption0: 1}, fluidConnection3: {sorption0: 1}, fluidConnection4: {sorption0: 1}, fluidConnection5: {sorption0: 1}, id: "nuclearcraftneohaul:turbine_outlet", isRedstonePowered: 0b, radiationLevel: 0.0d, redstoneControl: 0b, zcvase_payload: {multiblockData: {angVel: 0.0f, basePowerPerMB: 0.0d, bearingTension: 0.0d, bladeLength: 0, computerActivated: 0b, conductivity: 0.0d, dynamoCoilCount: 0, dynamoCoilCountOpposite: 0, effectiveMaxLength: 24, energyStorage: {capacity: 32000L, energy: 0L, maxTransfer: 16000}, expansionLevels: {}, flowDir: -1, idealTotalExpansionLevel: 1.0d, isProcessing: 0b, isTurbineOn: 0b, logic: {}, logicID: "turbine", maxBladeExpansionCoefficient: 1.0d, maxStatorExpansionCoefficient: 4.9E-324d, minBladeExpansionCoefficient: 1.7976931348623157E308d, minStatorExpansionCoefficient: 1.0d, noBladeSets: 0, particleEffect: "cloud", particleSpeedMult: 0.04310344827586207d, power: 0.0d, powerBonus: 0.0d, rawBladeEfficiencies: {}, rawPower: 0.0d, recipeInputRate: 0, recipeInputRateFP: 0.0d, rotorAngle: 0.0f, rotorEfficiency: 0.0d, shaftVolume: 0, shaftWidth: 0, spinUpMultiplier: 1.0d, tanks0: {capacity: 1000}, tanks1: {capacity: 4000}, totalExpansionLevel: 1.0d}}, zcvase_version: -1}},
        {pos: [3, 0, 3], state: "nuclearcraftneohaul:steel_turbine_rotor_blade{dir:y}", nbt: {alternateComparator: 0b, bladeDir: 2, id: "nuclearcraftneohaul:turbine_rotor_blade", isRedstonePowered: 0b, radiationLevel: 0.0d, redstoneControl: 0b, zcvase_payload: {}, zcvase_version: -1}},
        {pos: [3, 0, 4], state: "nuclearcraftneohaul:steel_turbine_rotor_blade{dir:y}", nbt: {alternateComparator: 0b, bladeDir: 2, id: "nuclearcraftneohaul:turbine_rotor_blade", isRedstonePowered: 0b, radiationLevel: 0.0d, redstoneControl: 0b, zcvase_payload: {}, zcvase_version: -1}},
        {pos: [4, 0, 3], state: "nuclearcraftneohaul:extreme_alloy_turbine_rotor_blade{dir:y}", nbt: {alternateComparator: 0b, bladeDir: 2, id: "nuclearcraftneohaul:turbine_rotor_blade", isRedstonePowered: 0b, radiationLevel: 0.0d, redstoneControl: 0b, zcvase_payload: {}, zcvase_version: -1}},
        {pos: [4, 0, 4], state: "nuclearcraftneohaul:extreme_alloy_turbine_rotor_blade{dir:y}", nbt: {alternateComparator: 0b, bladeDir: 2, id: "nuclearcraftneohaul:turbine_rotor_blade", isRedstonePowered: 0b, radiationLevel: 0.0d, redstoneControl: 0b, zcvase_payload: {}, zcvase_version: -1}},
        {pos: [5, 0, 3], state: "nuclearcraftneohaul:steel_turbine_rotor_blade{dir:y}", nbt: {alternateComparator: 0b, bladeDir: 2, id: "nuclearcraftneohaul:turbine_rotor_blade", isRedstonePowered: 0b, radiationLevel: 0.0d, redstoneControl: 0b, zcvase_payload: {}, zcvase_version: -1}},
        {pos: [5, 0, 4], state: "nuclearcraftneohaul:steel_turbine_rotor_blade{dir:y}", nbt: {alternateComparator: 0b, bladeDir: 2, id: "nuclearcraftneohaul:turbine_rotor_blade", isRedstonePowered: 0b, radiationLevel: 0.0d, redstoneControl: 0b, zcvase_payload: {}, zcvase_version: -1}},
        {pos: [6, 0, 3], state: "nuclearcraftneohaul:turbine_inlet{facing:east}", nbt: {alternateComparator: 0b, fluidConnection0: {sorption0: 0}, fluidConnection1: {sorption0: 0}, fluidConnection2: {sorption0: 0}, fluidConnection3: {sorption0: 0}, fluidConnection4: {sorption0: 0}, fluidConnection5: {sorption0: 0}, id: "nuclearcraftneohaul:turbine_inlet", isRedstonePowered: 0b, radiationLevel: 0.0d, redstoneControl: 0b, zcvase_payload: {}, zcvase_version: -1}},
        {pos: [2, 1, 3], state: "nuclearcraftneohaul:turbine_rotor_bearing", nbt: {alternateComparator: 0b, id: "nuclearcraftneohaul:turbine_rotor_bearing", isRedstonePowered: 0b, radiationLevel: 0.0d, redstoneControl: 0b, zcvase_payload: {}, zcvase_version: -1}},
        {pos: [2, 1, 4], state: "nuclearcraftneohaul:turbine_rotor_bearing", nbt: {alternateComparator: 0b, id: "nuclearcraftneohaul:turbine_rotor_bearing", isRedstonePowered: 0b, radiationLevel: 0.0d, redstoneControl: 0b, zcvase_payload: {}, zcvase_version: -1}},
        {pos: [3, 1, 2], state: "nuclearcraftneohaul:steel_turbine_rotor_blade{dir:z}", nbt: {alternateComparator: 0b, bladeDir: 2, id: "nuclearcraftneohaul:turbine_rotor_blade", isRedstonePowered: 0b, radiationLevel: 0.0d, redstoneControl: 0b, zcvase_payload: {}, zcvase_version: -1}},
        {pos: [3, 1, 3], state: "nuclearcraftneohaul:turbine_rotor_shaft{dir:x}", nbt: {alternateComparator: 0b, id: "nuclearcraftneohaul:turbine_rotor_shaft", isRedstonePowered: 0b, radiationLevel: 0.0d, redstoneControl: 0b, zcvase_payload: {}, zcvase_version: -1}},
        {pos: [3, 1, 4], state: "nuclearcraftneohaul:turbine_rotor_shaft{dir:x}", nbt: {alternateComparator: 0b, id: "nuclearcraftneohaul:turbine_rotor_shaft", isRedstonePowered: 0b, radiationLevel: 0.0d, redstoneControl: 0b, zcvase_payload: {}, zcvase_version: -1}},
        {pos: [3, 1, 5], state: "nuclearcraftneohaul:steel_turbine_rotor_blade{dir:z}", nbt: {alternateComparator: 0b, bladeDir: 2, id: "nuclearcraftneohaul:turbine_rotor_blade", isRedstonePowered: 0b, radiationLevel: 0.0d, redstoneControl: 0b, zcvase_payload: {}, zcvase_version: -1}},
        {pos: [4, 1, 2], state: "nuclearcraftneohaul:extreme_alloy_turbine_rotor_blade{dir:z}", nbt: {alternateComparator: 0b, bladeDir: 2, id: "nuclearcraftneohaul:turbine_rotor_blade", isRedstonePowered: 0b, radiationLevel: 0.0d, redstoneControl: 0b, zcvase_payload: {}, zcvase_version: -1}},
        {pos: [4, 1, 3], state: "nuclearcraftneohaul:turbine_rotor_shaft{dir:x}", nbt: {alternateComparator: 0b, id: "nuclearcraftneohaul:turbine_rotor_shaft", isRedstonePowered: 0b, radiationLevel: 0.0d, redstoneControl: 0b, zcvase_payload: {}, zcvase_version: -1}},
        {pos: [4, 1, 4], state: "nuclearcraftneohaul:turbine_rotor_shaft{dir:x}", nbt: {alternateComparator: 0b, id: "nuclearcraftneohaul:turbine_rotor_shaft", isRedstonePowered: 0b, radiationLevel: 0.0d, redstoneControl: 0b, zcvase_payload: {}, zcvase_version: -1}},
        {pos: [4, 1, 5], state: "nuclearcraftneohaul:extreme_alloy_turbine_rotor_blade{dir:z}", nbt: {alternateComparator: 0b, bladeDir: 2, id: "nuclearcraftneohaul:turbine_rotor_blade", isRedstonePowered: 0b, radiationLevel: 0.0d, redstoneControl: 0b, zcvase_payload: {}, zcvase_version: -1}},
        {pos: [5, 1, 2], state: "nuclearcraftneohaul:steel_turbine_rotor_blade{dir:z}", nbt: {alternateComparator: 0b, bladeDir: 2, id: "nuclearcraftneohaul:turbine_rotor_blade", isRedstonePowered: 0b, radiationLevel: 0.0d, redstoneControl: 0b, zcvase_payload: {}, zcvase_version: -1}},
        {pos: [5, 1, 3], state: "nuclearcraftneohaul:turbine_rotor_shaft{dir:x}", nbt: {alternateComparator: 0b, id: "nuclearcraftneohaul:turbine_rotor_shaft", isRedstonePowered: 0b, radiationLevel: 0.0d, redstoneControl: 0b, zcvase_payload: {}, zcvase_version: -1}},
        {pos: [5, 1, 4], state: "nuclearcraftneohaul:turbine_rotor_shaft{dir:x}", nbt: {alternateComparator: 0b, id: "nuclearcraftneohaul:turbine_rotor_shaft", isRedstonePowered: 0b, radiationLevel: 0.0d, redstoneControl: 0b, zcvase_payload: {}, zcvase_version: -1}},
        {pos: [5, 1, 5], state: "nuclearcraftneohaul:steel_turbine_rotor_blade{dir:z}", nbt: {alternateComparator: 0b, bladeDir: 2, id: "nuclearcraftneohaul:turbine_rotor_blade", isRedstonePowered: 0b, radiationLevel: 0.0d, redstoneControl: 0b, zcvase_payload: {}, zcvase_version: -1}},
        {pos: [6, 1, 3], state: "nuclearcraftneohaul:turbine_rotor_bearing", nbt: {alternateComparator: 0b, id: "nuclearcraftneohaul:turbine_rotor_bearing", isRedstonePowered: 0b, radiationLevel: 0.0d, redstoneControl: 0b, zcvase_payload: {}, zcvase_version: -1}},
        {pos: [6, 1, 4], state: "nuclearcraftneohaul:turbine_rotor_bearing", nbt: {alternateComparator: 0b, id: "nuclearcraftneohaul:turbine_rotor_bearing", isRedstonePowered: 0b, radiationLevel: 0.0d, redstoneControl: 0b, zcvase_payload: {}, zcvase_version: -1}},
        {pos: [2, 2, 3], state: "nuclearcraftneohaul:turbine_rotor_bearing", nbt: {alternateComparator: 0b, id: "nuclearcraftneohaul:turbine_rotor_bearing", isRedstonePowered: 0b, radiationLevel: 0.0d, redstoneControl: 0b, zcvase_payload: {}, zcvase_version: -1}},
        {pos: [2, 2, 4], state: "nuclearcraftneohaul:turbine_rotor_bearing", nbt: {alternateComparator: 0b, id: "nuclearcraftneohaul:turbine_rotor_bearing", isRedstonePowered: 0b, radiationLevel: 0.0d, redstoneControl: 0b, zcvase_payload: {}, zcvase_version: -1}},
        {pos: [3, 2, 2], state: "nuclearcraftneohaul:steel_turbine_rotor_blade{dir:z}", nbt: {alternateComparator: 0b, bladeDir: 2, id: "nuclearcraftneohaul:turbine_rotor_blade", isRedstonePowered: 0b, radiationLevel: 0.0d, redstoneControl: 0b, zcvase_payload: {}, zcvase_version: -1}},
        {pos: [3, 2, 3], state: "nuclearcraftneohaul:turbine_rotor_shaft{dir:x}", nbt: {alternateComparator: 0b, id: "nuclearcraftneohaul:turbine_rotor_shaft", isRedstonePowered: 0b, radiationLevel: 0.0d, redstoneControl: 0b, zcvase_payload: {}, zcvase_version: -1}},
        {pos: [3, 2, 4], state: "nuclearcraftneohaul:turbine_rotor_shaft{dir:x}", nbt: {alternateComparator: 0b, id: "nuclearcraftneohaul:turbine_rotor_shaft", isRedstonePowered: 0b, radiationLevel: 0.0d, redstoneControl: 0b, zcvase_payload: {}, zcvase_version: -1}},
        {pos: [3, 2, 5], state: "nuclearcraftneohaul:steel_turbine_rotor_blade{dir:z}", nbt: {alternateComparator: 0b, bladeDir: 2, id: "nuclearcraftneohaul:turbine_rotor_blade", isRedstonePowered: 0b, radiationLevel: 0.0d, redstoneControl: 0b, zcvase_payload: {}, zcvase_version: -1}},
        {pos: [4, 2, 2], state: "nuclearcraftneohaul:extreme_alloy_turbine_rotor_blade{dir:z}", nbt: {alternateComparator: 0b, bladeDir: 2, id: "nuclearcraftneohaul:turbine_rotor_blade", isRedstonePowered: 0b, radiationLevel: 0.0d, redstoneControl: 0b, zcvase_payload: {}, zcvase_version: -1}},
        {pos: [4, 2, 3], state: "nuclearcraftneohaul:turbine_rotor_shaft{dir:x}", nbt: {alternateComparator: 0b, id: "nuclearcraftneohaul:turbine_rotor_shaft", isRedstonePowered: 0b, radiationLevel: 0.0d, redstoneControl: 0b, zcvase_payload: {}, zcvase_version: -1}},
        {pos: [4, 2, 4], state: "nuclearcraftneohaul:turbine_rotor_shaft{dir:x}", nbt: {alternateComparator: 0b, id: "nuclearcraftneohaul:turbine_rotor_shaft", isRedstonePowered: 0b, radiationLevel: 0.0d, redstoneControl: 0b, zcvase_payload: {}, zcvase_version: -1}},
        {pos: [4, 2, 5], state: "nuclearcraftneohaul:extreme_alloy_turbine_rotor_blade{dir:z}", nbt: {alternateComparator: 0b, bladeDir: 2, id: "nuclearcraftneohaul:turbine_rotor_blade", isRedstonePowered: 0b, radiationLevel: 0.0d, redstoneControl: 0b, zcvase_payload: {}, zcvase_version: -1}},
        {pos: [5, 2, 2], state: "nuclearcraftneohaul:steel_turbine_rotor_blade{dir:z}", nbt: {alternateComparator: 0b, bladeDir: 2, id: "nuclearcraftneohaul:turbine_rotor_blade", isRedstonePowered: 0b, radiationLevel: 0.0d, redstoneControl: 0b, zcvase_payload: {}, zcvase_version: -1}},
        {pos: [5, 2, 3], state: "nuclearcraftneohaul:turbine_rotor_shaft{dir:x}", nbt: {alternateComparator: 0b, id: "nuclearcraftneohaul:turbine_rotor_shaft", isRedstonePowered: 0b, radiationLevel: 0.0d, redstoneControl: 0b, zcvase_payload: {}, zcvase_version: -1}},
        {pos: [5, 2, 4], state: "nuclearcraftneohaul:turbine_rotor_shaft{dir:x}", nbt: {alternateComparator: 0b, id: "nuclearcraftneohaul:turbine_rotor_shaft", isRedstonePowered: 0b, radiationLevel: 0.0d, redstoneControl: 0b, zcvase_payload: {}, zcvase_version: -1}},
        {pos: [5, 2, 5], state: "nuclearcraftneohaul:steel_turbine_rotor_blade{dir:z}", nbt: {alternateComparator: 0b, bladeDir: 2, id: "nuclearcraftneohaul:turbine_rotor_blade", isRedstonePowered: 0b, radiationLevel: 0.0d, redstoneControl: 0b, zcvase_payload: {}, zcvase_version: -1}},
        {pos: [6, 2, 3], state: "nuclearcraftneohaul:turbine_rotor_bearing", nbt: {alternateComparator: 0b, id: "nuclearcraftneohaul:turbine_rotor_bearing", isRedstonePowered: 0b, radiationLevel: 0.0d, redstoneControl: 0b, zcvase_payload: {}, zcvase_version: -1}},
        {pos: [6, 2, 4], state: "nuclearcraftneohaul:turbine_rotor_bearing", nbt: {alternateComparator: 0b, id: "nuclearcraftneohaul:turbine_rotor_bearing", isRedstonePowered: 0b, radiationLevel: 0.0d, redstoneControl: 0b, zcvase_payload: {}, zcvase_version: -1}},
        {pos: [3, 3, 3], state: "nuclearcraftneohaul:steel_turbine_rotor_blade{dir:y}", nbt: {alternateComparator: 0b, bladeDir: 2, id: "nuclearcraftneohaul:turbine_rotor_blade", isRedstonePowered: 0b, radiationLevel: 0.0d, redstoneControl: 0b, zcvase_payload: {}, zcvase_version: -1}},
        {pos: [3, 3, 4], state: "nuclearcraftneohaul:steel_turbine_rotor_blade{dir:y}", nbt: {alternateComparator: 0b, bladeDir: 2, id: "nuclearcraftneohaul:turbine_rotor_blade", isRedstonePowered: 0b, radiationLevel: 0.0d, redstoneControl: 0b, zcvase_payload: {}, zcvase_version: -1}},
        {pos: [4, 3, 3], state: "nuclearcraftneohaul:extreme_alloy_turbine_rotor_blade{dir:y}", nbt: {alternateComparator: 0b, bladeDir: 2, id: "nuclearcraftneohaul:turbine_rotor_blade", isRedstonePowered: 0b, radiationLevel: 0.0d, redstoneControl: 0b, zcvase_payload: {}, zcvase_version: -1}},
        {pos: [4, 3, 4], state: "nuclearcraftneohaul:extreme_alloy_turbine_rotor_blade{dir:y}", nbt: {alternateComparator: 0b, bladeDir: 2, id: "nuclearcraftneohaul:turbine_rotor_blade", isRedstonePowered: 0b, radiationLevel: 0.0d, redstoneControl: 0b, zcvase_payload: {}, zcvase_version: -1}},
        {pos: [5, 3, 3], state: "nuclearcraftneohaul:steel_turbine_rotor_blade{dir:y}", nbt: {alternateComparator: 0b, bladeDir: 2, id: "nuclearcraftneohaul:turbine_rotor_blade", isRedstonePowered: 0b, radiationLevel: 0.0d, redstoneControl: 0b, zcvase_payload: {}, zcvase_version: -1}},
        {pos: [5, 3, 4], state: "nuclearcraftneohaul:steel_turbine_rotor_blade{dir:y}", nbt: {alternateComparator: 0b, bladeDir: 2, id: "nuclearcraftneohaul:turbine_rotor_blade", isRedstonePowered: 0b, radiationLevel: 0.0d, redstoneControl: 0b, zcvase_payload: {}, zcvase_version: -1}}
    ],
    entities: [],
    palette: [
        "nuclearcraftneohaul:turbine_outlet{facing:west}",
        "nuclearcraftneohaul:steel_turbine_rotor_blade{dir:y}",
        "nuclearcraftneohaul:extreme_alloy_turbine_rotor_blade{dir:y}",
        "nuclearcraftneohaul:turbine_inlet{facing:east}",
        "nuclearcraftneohaul:turbine_rotor_bearing",
        "nuclearcraftneohaul:steel_turbine_rotor_blade{dir:z}",
        "nuclearcraftneohaul:turbine_rotor_shaft{dir:x}",
        "nuclearcraftneohaul:extreme_alloy_turbine_rotor_blade{dir:z}"
    ]
}